Workbook

Sheet 🏠 PAINEL
B2: 🛒 MARKETPLACE — PAINEL EXECUTIVO
B7: META ANUAL MKTPLACES | F7: REAL ANUAL MKTPLACES | J7: ATG% vs Meta | N7: ACOS MEDIO
B8: =IFERROR(SUM('📊 ANUAL MKTPLACES'!C4:N4),"-") -> 0 | F8: =IFERROR(SUM('📊 ANUAL MKTPLACES'!C5:N5),"-") -> 0 | J8: =IFERROR(SUM('📊 ANUAL MKTPLACES'!C5:N5)/SUM('📊 ANUAL MKTPLACES'!C4:N4),"-") -> - | N8: =IFERROR(SUM('📊 ANUAL MKTPLACES'!C8:N8)/SUM('📊 ANUAL MKTPLACES'!C5:N5),"-") -> -
B12: 📅 RECEITA MARKETPLACE POR MÊS — META × REAL
C13: JAN | D13: FEV | E13: MAR | F13: ABR | G13: MAI | H13: JUN | I13: JUL | J13: AGO | K13: SET | L13: OUT | M13: NOV | N13: DEZ | O13: TOTAL
B14: META (R$) | C14: =IFERROR('📊 ANUAL MKTPLACES'!C4,"-") -> 0 | D14: =IFERROR('📊 ANUAL MKTPLACES'!D4,"-") -> 0 | E14: =IFERROR('📊 ANUAL MKTPLACES'!E4,"-") -> 0 | F14: =IFERROR('📊 ANUAL MKTPLACES'!F4,"-") -> 0 | G14: =IFERROR('📊 ANUAL MKTPLACES'!G4,"-") -> 0 | H14: =IFERROR('📊 ANUAL MKTPLACES'!H4,"-") -> 0 | I14: =IFERROR('📊 ANUAL MKTPLACES'!I4,"-") -> 0 | J14: =IFERROR('📊 ANUAL MKTPLACES'!J4,"-") -> 0 | ... N14: =IFERROR('📊 ANUAL MKTPLACES'!N4,"-") -> 0 | Q14: =IFERROR('📊 ANUAL MKTPLACES'!N4,"-") -> 0
B15: REAL (R$) | C15: =IFERROR('📊 ANUAL MKTPLACES'!C5,"-") -> 0 | D15: =IFERROR('📊 ANUAL MKTPLACES'!D5,"-") -> 0 | E15: =IFERROR('📊 ANUAL MKTPLACES'!E5,"-") -> 0 | F15: =IFERROR('📊 ANUAL MKTPLACES'!F5,"-") -> 0 | G15: =IFERROR('📊 ANUAL MKTPLACES'!G5,"-") -> 0 | H15: =IFERROR('📊 ANUAL MKTPLACES'!H5,"-") -> 0 | I15: =IFERROR('📊 ANUAL MKTPLACES'!I5,"-") -> 0 | J15: =IFERROR('📊 ANUAL MKTPLACES'!J5,"-") -> 0 | ... N15: =IFERROR('📊 ANUAL MKTPLACES'!N5,"-") -> 0 | Q15: =IFERROR('📊 ANUAL MKTPLACES'!N5,"-") -> 0
B16: ATG% | C16: =IFERROR('📊 ANUAL MKTPLACES'!C6,"-") -> 0 | D16: =IFERROR('📊 ANUAL MKTPLACES'!D6,"-") -> 0 | E16: =IFERROR('📊 ANUAL MKTPLACES'!E6,"-") -> 0 | F16: =IFERROR('📊 ANUAL MKTPLACES'!F6,"-") -> 0 | G16: =IFERROR('📊 ANUAL MKTPLACES'!G6,"-") -> 0 | H16: =IFERROR('📊 ANUAL MKTPLACES'!H6,"-") -> 0 | I16: =IFERROR('📊 ANUAL MKTPLACES'!I6,"-") -> 0 | J16: =IFERROR('📊 ANUAL MKTPLACES'!J6,"-") -> 0 | ... N16: =IFERROR('📊 ANUAL MKTPLACES'!N6,"-") -> 0 | Q16: =IFERROR('📊 ANUAL MKTPLACES'!N6,"-") -> 0
B17: ADS (R$) | C17: =IFERROR('📊 ANUAL MKTPLACES'!C8,"-") | D17: =IFERROR('📊 ANUAL MKTPLACES'!D8,"-") | E17: =IFERROR('📊 ANUAL MKTPLACES'!E8,"-") | F17: =IFERROR('📊 ANUAL MKTPLACES'!F8,"-") | G17: =IFERROR('📊 ANUAL MKTPLACES'!G8,"-") | H17: =IFERROR('📊 ANUAL MKTPLACES'!H8,"-") | I17: =IFERROR('📊 ANUAL MKTPLACES'!I8,"-") | J17: =IFERROR('📊 ANUAL MKTPLACES'!J8,"-") | ... N17: =IFERROR('📊 ANUAL MKTPLACES'!N8,"-") -> - | Q17: =IFERROR('📊 ANUAL MKTPLACES'!N7,"-") -> -
B18: ACOS | C18: =IFERROR('📊 ANUAL MKTPLACES'!C9,"-") -> 0 | D18: =IFERROR('📊 ANUAL MKTPLACES'!D9,"-") -> 0 | E18: =IFERROR('📊 ANUAL MKTPLACES'!E9,"-") -> 0 | F18: =IFERROR('📊 ANUAL MKTPLACES'!F9,"-") -> 0 | G18: =IFERROR('📊 ANUAL MKTPLACES'!G9,"-") -> 0 | H18: =IFERROR('📊 ANUAL MKTPLACES'!H9,"-") -> 0 | I18: =IFERROR('📊 ANUAL MKTPLACES'!I9,"-") -> 0 | J18: =IFERROR('📊 ANUAL MKTPLACES'!J9,"-") -> 0 | ... N18: =IFERROR('📊 ANUAL MKTPLACES'!N9,"-") -> 0 | Q18: =IFERROR('📊 ANUAL MKTPLACES'!N8,"-") -> -
B21: 🛒 CANAIS — SHARE % (defina o share de cada canal)
B22: Canal | C22: Share % | D22: Meta Estimada (R$)
B23: Mercado Livre | D23: =IFERROR(C23*SUM('📊 ANUAL MKTPLACES'!C4:N4),"-") -> 0
B24: Shopee | D24: =IFERROR(C24*SUM('📊 ANUAL MKTPLACES'!C4:N4),"-") -> 0
B25: Amazon | D25: =IFERROR(C25*SUM('📊 ANUAL MKTPLACES'!C4:N4),"-") -> 0
B26: Magalu | D26: =IFERROR(C26*SUM('📊 ANUAL MKTPLACES'!C4:N4),"-") -> 0
B27: 2P / Full | D27: =IFERROR(C27*SUM('📊 ANUAL MKTPLACES'!C4:N4),"-") -> 0
B30: 📅 MACRO-CALENDÁRIO SAZONAL
B31: JAN | C31: FEV | D31: MAR | E31: ABR | F31: MAI | G31: JUN | H31: JUL | I31: AGO | J31: SET | K31: OUT | L31: NOV | M31: DEZ
B32: Verão | C32: Verão / Carnaval | D32: Mês do Consumidor | E32: Páscoa | F32: Dia das Mães | G32: Dia dos Namorados | H32: Copa / Férias | I32: Dia dos Pais | J32: Mês do Cliente | K32: Oktoberfest | L32: Black Friday | M32: Natal
B35: 📌 ABAS: 🏠 PAINEL | 📋 PLANO ESTRATÉGICO | 📅 TÁTICO SAZONAL | 📊 ANUAL MKTPLACES | 🛒 CANAIS | 📆 Q2 DIÁRIO | 📈 SEMANAL

Sheet 📋 PLANO ESTRATÉGICO
A1: 📋 PLANO ESTRATÉGICO — MARKETPLACE MULTI-CANAL
A2: MACRO ENTREGAS | B2: Verão | C2: Verão / Carnaval | D2: Mês do Consumidor | E2: Páscoa | F2: Dia das Mães | G2: Dia dos Namorados | H2: Copa / Férias | I2: Dia dos Pais | J2: Mês do Cliente | K2: Oktoberfest | L2: Black Friday | M2: Natal | N2: TOTAL
B3: JAN | C3: FEV | D3: MAR | E3: ABR | F3: MAI | G3: JUN | H3: JUL | I3: AGO | J3: SET | K3: OUT | L3: NOV | M3: DEZ
A4: ▶ META ANUAL — RECEITA
A5: Receita META 2025 (R$) | N5: =IFERROR(SUM(B5:M5),"-") -> 0
A6: Receita REAL 2025 (R$) | N6: =IFERROR(SUM(B6:M6),"-") -> 0
A7: ATG% vs Meta 2025 | B7: =IFERROR(B6/B5,"-") -> - | C7: =IFERROR(C6/C5,"-") -> - | D7: =IFERROR(D6/D5,"-") -> - | E7: =IFERROR(E6/E5,"-") -> - | F7: =IFERROR(F6/F5,"-") -> - | G7: =IFERROR(G6/G5,"-") -> - | H7: =IFERROR(H6/H5,"-") -> - | I7: =IFERROR(I6/I5,"-") -> - | ... M7: =IFERROR(M6/M5,"-") -> - | N7: =IFERROR(AVERAGEIF(B7:M7,">0"),"-") -> -
A8: YOY% 2025 (coluna livre) | B8: =IFERROR("","") | C8: =IFERROR("","") | D8: =IFERROR("","") | E8: =IFERROR("","") | F8: =IFERROR("","") | G8: =IFERROR("","") | H8: =IFERROR("","") | I8: =IFERROR("","") | ... M8: =IFERROR("","") | N8: =IFERROR(AVERAGEIF(B8:M8,">0"),"-") -> -
A9: Receita META 2026 (R$) | N9: =IFERROR(SUM(B9:M9),"-") -> 0
A10: Receita REAL 2026 (R$) | N10: =IFERROR(SUM(B10:M10),"-") -> 0
A11: ATG% vs Meta 2026 | B11: =IFERROR(B10/B9,"-") -> - | C11: =IFERROR(C10/C9,"-") -> - | D11: =IFERROR(D10/D9,"-") -> - | E11: =IFERROR(E10/E9,"-") -> - | F11: =IFERROR(F10/F9,"-") -> - | G11: =IFERROR(G10/G9,"-") -> - | H11: =IFERROR(H10/H9,"-") -> - | I11: =IFERROR(I10/I9,"-") -> - | ... M11: =IFERROR(M10/M9,"-") -> - | N11: =IFERROR(AVERAGEIF(B11:M11,">0"),"-") -> -
A12: YOY% 2026 vs 2025 | B12: =IFERROR(IF(B6=0,"-",B10/B6-1),"-") -> - | C12: =IFERROR(IF(C6=0,"-",C10/C6-1),"-") -> - | D12: =IFERROR(IF(D6=0,"-",D10/D6-1),"-") -> - | E12: =IFERROR(IF(E6=0,"-",E10/E6-1),"-") -> - | F12: =IFERROR(IF(F6=0,"-",F10/F6-1),"-") -> - | G12: =IFERROR(IF(G6=0,"-",G10/G6-1),"-") -> - | H12: =IFERROR(IF(H6=0,"-",H10/H6-1),"-") -> - | I12: =IFERROR(IF(I6=0,"-",I10/I6-1),"-") -> - | ... M12: =IFERROR(IF(M6=0,"-",M10/M6-1),"-") -> - | N12: =IFERROR(AVERAGEIF(B12:M12,">0"),"-") -> -
A14: ▶ ADS & MARKETING
A15: Investimento ADS META 2025 (R$) | N15: =IFERROR(SUM(B15:M15),"-") -> 0
A16: Investimento ADS REAL 2025 (R$) | N16: =IFERROR(SUM(B16:M16),"-") -> 0
A17: ACOS META 2025 | B17: =IFERROR(B15/B5,"-") -> - | C17: =IFERROR(C15/C5,"-") -> - | D17: =IFERROR(D15/D5,"-") -> - | E17: =IFERROR(E15/E5,"-") -> - | F17: =IFERROR(F15/F5,"-") -> - | G17: =IFERROR(G15/G5,"-") -> - | H17: =IFERROR(H15/H5,"-") -> - | I17: =IFERROR(I15/I5,"-") -> - | ... M17: =IFERROR(M15/M5,"-") -> - | N17: =IFERROR(AVERAGEIF(B17:M17,">0"),"-") -> -
A18: ACOS REAL 2025 | B18: =IFERROR(B16/B6,"-") -> - | C18: =IFERROR(C16/C6,"-") -> - | D18: =IFERROR(D16/D6,"-") -> - | E18: =IFERROR(E16/E6,"-") -> - | F18: =IFERROR(F16/F6,"-") -> - | G18: =IFERROR(G16/G6,"-") -> - | H18: =IFERROR(H16/H6,"-") -> - | I18: =IFERROR(I16/I6,"-") -> - | ... M18: =IFERROR(M16/M6,"-") -> - | N18: =IFERROR(AVERAGEIF(B18:M18,">0"),"-") -> -
A19: ROAS REAL 2025 | B19: =IFERROR(B6/B16,"-") -> - | C19: =IFERROR(C6/C16,"-") -> - | D19: =IFERROR(D6/D16,"-") -> - | E19: =IFERROR(E6/E16,"-") -> - | F19: =IFERROR(F6/F16,"-") -> - | G19: =IFERROR(G6/G16,"-") -> - | H19: =IFERROR(H6/H16,"-") -> - | I19: =IFERROR(I6/I16,"-") -> - | ... M19: =IFERROR(M6/M16,"-") -> - | N19: =IFERROR(AVERAGEIF(B19:M19,">0"),"-") -> -
A20: Investimento ADS META 2026 (R$) | N20: =IFERROR(SUM(B20:M20),"-") -> 0
A21: Investimento ADS REAL 2026 (R$) | N21: =IFERROR(SUM(B21:M21),"-") -> 0
A22: ACOS META 2026 | B22: =IFERROR(B20/B9,"-") -> - | C22: =IFERROR(C20/C9,"-") -> - | D22: =IFERROR(D20/D9,"-") -> - | E22: =IFERROR(E20/E9,"-") -> - | F22: =IFERROR(F20/F9,"-") -> - | G22: =IFERROR(G20/G9,"-") -> - | H22: =IFERROR(H20/H9,"-") -> - | I22: =IFERROR(I20/I9,"-") -> - | ... M22: =IFERROR(M20/M9,"-") -> - | N22: =IFERROR(AVERAGEIF(B22:M22,">0"),"-") -> -
A23: ACOS REAL 2026 | B23: =IFERROR(B21/B10,"-") -> - | C23: =IFERROR(C21/C10,"-") -> - | D23: =IFERROR(D21/D10,"-") -> - | E23: =IFERROR(E21/E10,"-") -> - | F23: =IFERROR(F21/F10,"-") -> - | G23: =IFERROR(G21/G10,"-") -> - | H23: =IFERROR(H21/H10,"-") -> - | I23: =IFERROR(I21/I10,"-") -> - | ... M23: =IFERROR(M21/M10,"-") -> - | N23: =IFERROR(AVERAGEIF(B23:M23,">0"),"-") -> -
A24: ROAS REAL 2026 | B24: =IFERROR(B10/B21,"-") -> - | C24: =IFERROR(C10/C21,"-") -> - | D24: =IFERROR(D10/D21,"-") -> - | E24: =IFERROR(E10/E21,"-") -> - | F24: =IFERROR(F10/F21,"-") -> - | G24: =IFERROR(G10/G21,"-") -> - | H24: =IFERROR(H10/H21,"-") -> - | I24: =IFERROR(I10/I21,"-") -> - | ... M24: =IFERROR(M10/M21,"-") -> - | N24: =IFERROR(AVERAGEIF(B24:M24,">0"),"-") -> -
A26: ▶ DISTRIBUIÇÃO POR CANAL — META 2026
A27: Canal | B27: JAN | C27: FEV | D27: MAR | E27: ABR | F27: MAI | G27: JUN | H27: JUL | I27: AGO | J27: SET | K27: OUT | L27: NOV | M27: DEZ | N27: TOTAL | O27: Share%
A28: Share % (definir) | N28: 100%
A29: Mercado Livre | B29: =IFERROR(B9*O29,"-") -> 0 | C29: =IFERROR(C9*O29,"-") -> 0 | D29: =IFERROR(D9*O29,"-") -> 0 | E29: =IFERROR(E9*O29,"-") -> 0 | F29: =IFERROR(F9*O29,"-") -> 0 | G29: =IFERROR(G9*O29,"-") -> 0 | H29: =IFERROR(H9*O29,"-") -> 0 | I29: =IFERROR(I9*O29,"-") -> 0 | J29: =IFERROR(J9*O29,"-") -> 0 | K29: =IFERROR(K9*O29,"-") -> 0 | L29: =IFERROR(L9*O29,"-") -> 0 | M29: =IFERROR(M9*O29,"-") -> 0 | N29: =IFERROR(N9*O29,"-") -> 0
A30: Shopee | B30: =IFERROR(B9*O30,"-") -> 0 | C30: =IFERROR(C9*O30,"-") -> 0 | D30: =IFERROR(D9*O30,"-") -> 0 | E30: =IFERROR(E9*O30,"-") -> 0 | F30: =IFERROR(F9*O30,"-") -> 0 | G30: =IFERROR(G9*O30,"-") -> 0 | H30: =IFERROR(H9*O30,"-") -> 0 | I30: =IFERROR(I9*O30,"-") -> 0 | J30: =IFERROR(J9*O30,"-") -> 0 | K30: =IFERROR(K9*O30,"-") -> 0 | L30: =IFERROR(L9*O30,"-") -> 0 | M30: =IFERROR(M9*O30,"-") -> 0 | N30: =IFERROR(N9*O30,"-") -> 0
A31: Amazon | B31: =IFERROR(B9*O31,"-") -> 0 | C31: =IFERROR(C9*O31,"-") -> 0 | D31: =IFERROR(D9*O31,"-") -> 0 | E31: =IFERROR(E9*O31,"-") -> 0 | F31: =IFERROR(F9*O31,"-") -> 0 | G31: =IFERROR(G9*O31,"-") -> 0 | H31: =IFERROR(H9*O31,"-") -> 0 | I31: =IFERROR(I9*O31,"-") -> 0 | J31: =IFERROR(J9*O31,"-") -> 0 | K31: =IFERROR(K9*O31,"-") -> 0 | L31: =IFERROR(L9*O31,"-") -> 0 | M31: =IFERROR(M9*O31,"-") -> 0 | N31: =IFERROR(N9*O31,"-") -> 0
A32: Magalu | B32: =IFERROR(B9*O32,"-") -> 0 | C32: =IFERROR(C9*O32,"-") -> 0 | D32: =IFERROR(D9*O32,"-") -> 0 | E32: =IFERROR(E9*O32,"-") -> 0 | F32: =IFERROR(F9*O32,"-") -> 0 | G32: =IFERROR(G9*O32,"-") -> 0 | H32: =IFERROR(H9*O32,"-") -> 0 | I32: =IFERROR(I9*O32,"-") -> 0 | J32: =IFERROR(J9*O32,"-") -> 0 | K32: =IFERROR(K9*O32,"-") -> 0 | L32: =IFERROR(L9*O32,"-") -> 0 | M32: =IFERROR(M9*O32,"-") -> 0 | N32: =IFERROR(N9*O32,"-") -> 0
A33: 2P / Full | B33: =IFERROR(B9*O33,"-") -> 0 | C33: =IFERROR(C9*O33,"-") -> 0 | D33: =IFERROR(D9*O33,"-") -> 0 | E33: =IFERROR(E9*O33,"-") -> 0 | F33: =IFERROR(F9*O33,"-") -> 0 | G33: =IFERROR(G9*O33,"-") -> 0 | H33: =IFERROR(H9*O33,"-") -> 0 | I33: =IFERROR(I9*O33,"-") -> 0 | J33: =IFERROR(J9*O33,"-") -> 0 | K33: =IFERROR(K9*O33,"-") -> 0 | L33: =IFERROR(L9*O33,"-") -> 0 | M33: =IFERROR(M9*O33,"-") -> 0 | N33: =IFERROR(N9*O33,"-") -> 0

Sheet 📅 TÁTICO SAZONAL
A1: 📅 PLANO TÁTICO SAZONAL — MARKETPLACE
A2: CATEGORIA | B2: JAN | C2: FEV | D2: MAR | E2: ABR | F2: MAI | G2: JUN | H2: JUL | I2: AGO | J2: SET | K2: OUT | L2: NOV | M2: DEZ
A3: META MKTPLACES (R$) | B3: =IFERROR('📊 ANUAL MKTPLACES'!B4,"-") -> 0 | C3: =IFERROR('📊 ANUAL MKTPLACES'!C4,"-") -> 0 | D3: =IFERROR('📊 ANUAL MKTPLACES'!D4,"-") -> 0 | E3: =IFERROR('📊 ANUAL MKTPLACES'!E4,"-") -> 0 | F3: =IFERROR('📊 ANUAL MKTPLACES'!F4,"-") -> 0 | G3: =IFERROR('📊 ANUAL MKTPLACES'!G4,"-") -> 0 | H3: =IFERROR('📊 ANUAL MKTPLACES'!H4,"-") -> 0 | I3: =IFERROR('📊 ANUAL MKTPLACES'!I4,"-") -> 0 | ... M3: =IFERROR('📊 ANUAL MKTPLACES'!M4,"-") -> 0
A4: Evento / Data | E4: 04/04 - Ação 4.4 Marketplaces | F4: 01/05 - Dia do Trabalho | G4: 06/06 - Ação 6.6 Marketplaces | H4: 07/07 - Ação 7.7 Marketplaces | I4: 08/08 - Ação 8.8 Marketplaces | J4: 09/09 - Ação 9.9 Marketplaces | K4: 10/10 - Ação 10.10 Marketplaces | L4: 11/11 - Ação 11.11 Marketplaces | M4: 12/12 - Ação 12.12 Marketplaces
E5: 05/04 - Páscoa ⭐ | F5: 05/05 - Ação 5.5 Marketplaces | G5: 12/06 - Dia dos Namorados ⭐ | H5: 09-11/07 - Quartas de Final Copa | I5: 09/08 - Dia dos Pais ⭐⭐ | J5: 15/09 - Dia do Cliente ⭐ | K5: 12/10 - Dia da Criança ⭐ | L5: 27/11 - Black Friday 2026 ⭐⭐⭐ | M5: 25/12 - Natal ⭐⭐
E6: 21/04 - Tiradentes | F6: 10/05 - Dia das Mães ⭐⭐ | G6: 11/06 - Copa: 1º jogo Brasil | H6: 19/07 - Final Copa do Mundo ⭐ | I6: 18/08 - Dia do Estagiário | J6: 07/09 - Independência do Brasil | K6: 31/10 - Halloween | L6: 30/11 - Cyber Monday | M6: 31/12 - Réveillon
E7: 28/04 - Dia do Frete Grátis
A9: MACRO-OBJETIVOS ESTRATÉGICOS POR MÊS
A10: Macro-Objetivos | E10: Páscoa Prep. Copa Canal de reviews | F10: Copa (prep.) Nova plataforma Novos complementos | G10: Copa do Mundo Otimização ADS Expansão portfólio | H10: Final Copa Projeto arquitetos Expansão portfólio | I10: Dia dos Pais ⭐ Pipeline Q4 Projeto personaliz. | J10: Mês do Cliente Prep. BF Review catálogo | K10: Projetos especiais Campanha BF prep. Review preços | L10: Black Friday ⭐⭐⭐ Cyber Monday Novembro intenso | M10: Natal ⭐⭐ Review anual Planej. próximo ano

Sheet 📊 ANUAL MKTPLACES
A1: 📊 ACOMPANHAMENTO ANUAL — MARKETPLACE
A2: 📘 Azul = preencher | 📙 Amarelo = meta | ⬛ Fórmulas calculam automaticamente
A3: MÉTRICA | B3: JAN | C3: FEV | D3: MAR | E3: ABR | F3: MAI | G3: JUN | H3: JUL | I3: AGO | J3: SET | K3: OUT | L3: NOV | M3: DEZ | N3: TOTAL
A4: 💰 RECEITA MARKETPLACE
A5: Receita META 2025 (R$) | N5: =IFERROR(SUM(B5:M5),"-") -> 0
A6: Receita REAL 2025 (R$) | N6: =IFERROR(SUM(B6:M6),"-") -> 0
A7: ATG% vs Meta 2025 | B7: =IFERROR(B6/B5,"-") -> - | C7: =IFERROR(C6/C5,"-") -> - | D7: =IFERROR(D6/D5,"-") -> - | E7: =IFERROR(E6/E5,"-") -> - | F7: =IFERROR(F6/F5,"-") -> - | G7: =IFERROR(G6/G5,"-") -> - | H7: =IFERROR(H6/H5,"-") -> - | I7: =IFERROR(I6/I5,"-") -> - | ... M7: =IFERROR(M6/M5,"-") -> - | N7: =IFERROR(AVERAGEIF(B7:M7,">0"),"-") -> -
A8: YOY% 2025 vs ano anterior | B8: =IFERROR("","") | C8: =IFERROR("","") | D8: =IFERROR("","") | E8: =IFERROR("","") | F8: =IFERROR("","") | G8: =IFERROR("","") | H8: =IFERROR("","") | I8: =IFERROR("","") | ... M8: =IFERROR("","") | N8: =IFERROR(AVERAGEIF(B8:M8,">0"),"-") -> -
A9: Receita META 2026 (R$) | N9: =IFERROR(SUM(B9:M9),"-") -> 0
A10: Receita REAL 2026 (R$) | N10: =IFERROR(SUM(B10:M10),"-") -> 0
A11: ATG% vs Meta 2026 | B11: =IFERROR(B10/B9,"-") -> - | C11: =IFERROR(C10/C9,"-") -> - | D11: =IFERROR(D10/D9,"-") -> - | E11: =IFERROR(E10/E9,"-") -> - | F11: =IFERROR(F10/F9,"-") -> - | G11: =IFERROR(G10/G9,"-") -> - | H11: =IFERROR(H10/H9,"-") -> - | I11: =IFERROR(I10/I9,"-") -> - | ... M11: =IFERROR(M10/M9,"-") -> - | N11: =IFERROR(AVERAGEIF(B11:M11,">0"),"-") -> -
A12: YOY% 2026 vs 2025 | B12: =IFERROR(IF(B6=0,"-",B10/B6-1),"-") -> - | C12: =IFERROR(IF(C6=0,"-",C10/C6-1),"-") -> - | D12: =IFERROR(IF(D6=0,"-",D10/D6-1),"-") -> - | E12: =IFERROR(IF(E6=0,"-",E10/E6-1),"-") -> - | F12: =IFERROR(IF(F6=0,"-",F10/F6-1),"-") -> - | G12: =IFERROR(IF(G6=0,"-",G10/G6-1),"-") -> - | H12: =IFERROR(IF(H6=0,"-",H10/H6-1),"-") -> - | I12: =IFERROR(IF(I6=0,"-",I10/I6-1),"-") -> - | ... M12: =IFERROR(IF(M6=0,"-",M10/M6-1),"-") -> - | N12: =IFERROR(AVERAGEIF(B12:M12,">0"),"-") -> -
A13: Rec. META Acum. 2025 | B13: =SUM($B$5:B5) -> 0 | C13: =SUM($B$5:C5) -> 0 | D13: =SUM($B$5:D5) -> 0 | E13: =SUM($B$5:E5) -> 0 | F13: =SUM($B$5:F5) -> 0 | G13: =SUM($B$5:G5) -> 0 | H13: =SUM($B$5:H5) -> 0 | I13: =SUM($B$5:I5) -> 0 | ... M13: =SUM($B$5:M5) -> 0 | N13: =SUM(B5:M5) -> 0
A14: Rec. REAL Acum. 2025 | B14: =SUM($B$6:B6) -> 0 | C14: =SUM($B$6:C6) -> 0 | D14: =SUM($B$6:D6) -> 0 | E14: =SUM($B$6:E6) -> 0 | F14: =SUM($B$6:F6) -> 0 | G14: =SUM($B$6:G6) -> 0 | H14: =SUM($B$6:H6) -> 0 | I14: =SUM($B$6:I6) -> 0 | ... M14: =SUM($B$6:M6) -> 0 | N14: =SUM(B6:M6) -> 0
A15: Rec. META Acum. 2026 | B15: =SUM($B$9:B9) -> 0 | C15: =SUM($B$9:C9) -> 0 | D15: =SUM($B$9:D9) -> 0 | E15: =SUM($B$9:E9) -> 0 | F15: =SUM($B$9:F9) -> 0 | G15: =SUM($B$9:G9) -> 0 | H15: =SUM($B$9:H9) -> 0 | I15: =SUM($B$9:I9) -> 0 | ... M15: =SUM($B$9:M9) -> 0 | N15: =SUM(B9:M9) -> 0
A16: Rec. REAL Acum. 2026 | B16: =SUM($B$10:B10) -> 0 | C16: =SUM($B$10:C10) -> 0 | D16: =SUM($B$10:D10) -> 0 | E16: =SUM($B$10:E10) -> 0 | F16: =SUM($B$10:F10) -> 0 | G16: =SUM($B$10:G10) -> 0 | H16: =SUM($B$10:H10) -> 0 | I16: =SUM($B$10:I10) -> 0 | ... M16: =SUM($B$10:M10) -> 0 | N16: =SUM(B10:M10) -> 0
A18: 📣 ADS & MARKETING
A19: Investimento ADS META 2025 (R$) | N19: =IFERROR(SUM(B19:M19),"-") -> 0
A20: Investimento ADS REAL 2025 (R$) | N20: =IFERROR(SUM(B20:M20),"-") -> 0
A21: ACOS META 2025 | B21: =IFERROR(B19/B5,"-") -> - | C21: =IFERROR(C19/C5,"-") -> - | D21: =IFERROR(D19/D5,"-") -> - | E21: =IFERROR(E19/E5,"-") -> - | F21: =IFERROR(F19/F5,"-") -> - | G21: =IFERROR(G19/G5,"-") -> - | H21: =IFERROR(H19/H5,"-") -> - | I21: =IFERROR(I19/I5,"-") -> - | ... M21: =IFERROR(M19/M5,"-") -> - | N21: =IFERROR(AVERAGEIF(B21:M21,">0"),"-") -> -
A22: ACOS REAL 2025 | B22: =IFERROR(B20/B6,"-") -> - | C22: =IFERROR(C20/C6,"-") -> - | D22: =IFERROR(D20/D6,"-") -> - | E22: =IFERROR(E20/E6,"-") -> - | F22: =IFERROR(F20/F6,"-") -> - | G22: =IFERROR(G20/G6,"-") -> - | H22: =IFERROR(H20/H6,"-") -> - | I22: =IFERROR(I20/I6,"-") -> - | ... M22: =IFERROR(M20/M6,"-") -> - | N22: =IFERROR(AVERAGEIF(B22:M22,">0"),"-") -> -
A23: ROAS REAL 2025 | B23: =IFERROR(B6/B20,"-") -> - | C23: =IFERROR(C6/C20,"-") -> - | D23: =IFERROR(D6/D20,"-") -> - | E23: =IFERROR(E6/E20,"-") -> - | F23: =IFERROR(F6/F20,"-") -> - | G23: =IFERROR(G6/G20,"-") -> - | H23: =IFERROR(H6/H20,"-") -> - | I23: =IFERROR(I6/I20,"-") -> - | ... M23: =IFERROR(M6/M20,"-") -> - | N23: =IFERROR(AVERAGEIF(B23:M23,">0"),"-") -> -
A24: Investimento ADS META 2026 (R$) | N24: =IFERROR(SUM(B24:M24),"-") -> 0
A25: Investimento ADS REAL 2026 (R$) | N25: =IFERROR(SUM(B25:M25),"-") -> 0
A26: ACOS META 2026 | B26: =IFERROR(B24/B9,"-") -> - | C26: =IFERROR(C24/C9,"-") -> - | D26: =IFERROR(D24/D9,"-") -> - | E26: =IFERROR(E24/E9,"-") -> - | F26: =IFERROR(F24/F9,"-") -> - | G26: =IFERROR(G24/G9,"-") -> - | H26: =IFERROR(H24/H9,"-") -> - | I26: =IFERROR(I24/I9,"-") -> - | ... M26: =IFERROR(M24/M9,"-") -> - | N26: =IFERROR(AVERAGEIF(B26:M26,">0"),"-") -> -
A27: ACOS REAL 2026 | B27: =IFERROR(B25/B10,"-") -> - | C27: =IFERROR(C25/C10,"-") -> - | D27: =IFERROR(D25/D10,"-") -> - | E27: =IFERROR(E25/E10,"-") -> - | F27: =IFERROR(F25/F10,"-") -> - | G27: =IFERROR(G25/G10,"-") -> - | H27: =IFERROR(H25/H10,"-") -> - | I27: =IFERROR(I25/I10,"-") -> - | ... M27: =IFERROR(M25/M10,"-") -> - | N27: =IFERROR(AVERAGEIF(B27:M27,">0"),"-") -> -
A28: ROAS REAL 2026 | B28: =IFERROR(B10/B25,"-") -> - | C28: =IFERROR(C10/C25,"-") -> - | D28: =IFERROR(D10/D25,"-") -> - | E28: =IFERROR(E10/E25,"-") -> - | F28: =IFERROR(F10/F25,"-") -> - | G28: =IFERROR(G10/G25,"-") -> - | H28: =IFERROR(H10/H25,"-") -> - | I28: =IFERROR(I10/I25,"-") -> - | ... M28: =IFERROR(M10/M25,"-") -> - | N28: =IFERROR(AVERAGEIF(B28:M28,">0"),"-") -> -
A30: 📈 VOLUME & CONVERSÃO
A31: Visitas Projetadas | N31: =IFERROR(SUM(B31:M31),"-") -> 0
A32: Visitas Reais | N32: =IFERROR(SUM(B32:M32),"-") -> 0
A33: ATG% Visitas | B33: =IFERROR(B32/B31,"-") -> - | C33: =IFERROR(C32/C31,"-") -> - | D33: =IFERROR(D32/D31,"-") -> - | E33: =IFERROR(E32/E31,"-") -> - | F33: =IFERROR(F32/F31,"-") -> - | G33: =IFERROR(G32/G31,"-") -> - | H33: =IFERROR(H32/H31,"-") -> - | I33: =IFERROR(I32/I31,"-") -> - | ... M33: =IFERROR(M32/M31,"-") -> - | N33: =IFERROR(AVERAGEIF(B33:M33,">0"),"-") -> -
A34: # Pedidos / Transações | N34: =IFERROR(SUM(B34:M34),"-") -> 0
A35: Taxa de Conversão | B35: =IFERROR(B34/B32,"-") -> - | C35: =IFERROR(C34/C32,"-") -> - | D35: =IFERROR(D34/D32,"-") -> - | E35: =IFERROR(E34/E32,"-") -> - | F35: =IFERROR(F34/F32,"-") -> - | G35: =IFERROR(G34/G32,"-") -> - | H35: =IFERROR(H34/H32,"-") -> - | I35: =IFERROR(I34/I32,"-") -> - | ... M35: =IFERROR(M34/M32,"-") -> - | N35: =IFERROR(AVERAGEIF(B35:M35,">0"),"-") -> -
A36: Ticket Médio Real (R$) | B36: =IFERROR(B6/B34,"-") -> - | C36: =IFERROR(C6/C34,"-") -> - | D36: =IFERROR(D6/D34,"-") -> - | E36: =IFERROR(E6/E34,"-") -> - | F36: =IFERROR(F6/F34,"-") -> - | G36: =IFERROR(G6/G34,"-") -> - | H36: =IFERROR(H6/H34,"-") -> - | I36: =IFERROR(I6/I34,"-") -> - | ... M36: =IFERROR(M6/M34,"-") -> - | N36: =IFERROR(AVERAGEIF(B36:M36,">0"),"-") -> -
A38: 🛒 RECEITA REAL POR CANAL (R$)
A39: Mercado Livre | N39: =IFERROR(SUM(B39:M39),"-") -> 0
A40: Shopee | N40: =IFERROR(SUM(B40:M40),"-") -> 0
A41: Amazon | N41: =IFERROR(SUM(B41:M41),"-") -> 0
A42: Magalu | N42: =IFERROR(SUM(B42:M42),"-") -> 0
A43: 2P / Full | N43: =IFERROR(SUM(B43:M43),"-") -> 0
...

Sheet 🛒 CANAIS
A1: 🛒 PERFORMANCE POR CANAL — DETALHE MENSAL
A3: MERCADO LIVRE
A4: MÉTRICA | B4: JAN | C4: FEV | D4: MAR | E4: ABR | F4: MAI | G4: JUN | H4: JUL | I4: AGO | J4: SET | K4: OUT | L4: NOV | M4: DEZ | N4: TOTAL
A5: Receita META 2025 (R$) | N5: =IFERROR(SUM(B5:M5),"-") -> 0
A6: Receita REAL 2025 (R$) | N6: =IFERROR(SUM(B6:M6),"-") -> 0
A7: Receita META 2026 (R$) | N7: =IFERROR(SUM(B7:M7),"-") -> 0
A8: Receita REAL 2026 (R$) | C8: 50602 | D8: 60148 | E8: 120000 | N8: =IFERROR(SUM(B8:M8),"-") -> 230750
A9: ATG% Real vs Meta | B9: =IFERROR(B6/B5,"-") -> - | C9: =IFERROR(C6/C5,"-") -> - | D9: =IFERROR(D6/D5,"-") -> - | E9: =IFERROR(E6/E5,"-") -> - | F9: =IFERROR(F6/F5,"-") -> - | G9: =IFERROR(G6/G5,"-") -> - | H9: =IFERROR(H6/H5,"-") -> - | I9: =IFERROR(I6/I5,"-") -> - | ... N9: =IFERROR(N6/N5,"-") -> -
A10: Investimento ADS (R$) | C10: 2259 | D10: 3042 | E10: 3042 | N10: =IFERROR(SUM(B10:M10),"-") -> 8343
A11: ACOS (%) | B11: =IFERROR(B10/B6,"-") -> - | C11: =IFERROR(C10/C8,"-") -> 0.044642504 | D11: =IFERROR(D10/D8,"-") -> 0.050575248 | E11: =IFERROR(E10/E8,"-") -> 0.02535 | F11: =IFERROR(F10/F6,"-") -> - | G11: =IFERROR(G10/G6,"-") -> - | H11: =IFERROR(H10/H6,"-") -> - | I11: =IFERROR(I10/I6,"-") -> - | J11: =IFERROR(J10/J6,"-") -> - | K11: =IFERROR(K10/K6,"-") -> - | L11: =IFERROR(L10/L6,"-") -> - | M11: =IFERROR(M10/M6,"-") -> - | N11: =IFERROR(N10/N6,"-") -> -
A12: ROAS | B12: =IFERROR(B6/B10,"-") -> - | C12: =IFERROR(C8/C10,"-") -> 22.400177 | D12: =IFERROR(D8/D10,"-") -> 19.772518 | E12: =IFERROR(E8/E10,"-") -> 39.447732 | F12: =IFERROR(F6/F10,"-") -> - | G12: =IFERROR(G6/G10,"-") -> - | H12: =IFERROR(H6/H10,"-") -> - | I12: =IFERROR(I6/I10,"-") -> - | J12: =IFERROR(J6/J10,"-") -> - | K12: =IFERROR(K6/K10,"-") -> - | L12: =IFERROR(L6/L10,"-") -> - | M12: =IFERROR(M6/M10,"-") -> - | N12: =IFERROR(N6/N10,"-") -> 0
A13: # Pedidos | C13: 264 | D13: 335 | E13: 335 | N13: =IFERROR(SUM(B13:M13),"-") -> 934
A14: Ticket Médio (R$) | B14: =IFERROR(B6/B13,"-") -> - | C14: =IFERROR(C8/C13,"-") -> 191.67424 | D14: =IFERROR(D8/D13,"-") -> 179.54627 | E14: =IFERROR(E8/E13,"-") -> 358.20896 | F14: =IFERROR(F6/F13,"-") -> - | G14: =IFERROR(G6/G13,"-") -> - | H14: =IFERROR(H6/H13,"-") -> - | I14: =IFERROR(I6/I13,"-") -> - | J14: =IFERROR(J6/J13,"-") -> - | K14: =IFERROR(K6/K13,"-") -> - | L14: =IFERROR(L6/L13,"-") -> - | M14: =IFERROR(M6/M13,"-") -> - | N14: =IFERROR(N6/N13,"-") -> 0
A16: SHOPEE
A17: MÉTRICA | B17: JAN | C17: FEV | D17: MAR | E17: ABR | F17: MAI | G17: JUN | H17: JUL | I17: AGO | J17: SET | K17: OUT | L17: NOV | M17: DEZ | N17: TOTAL
A18: Receita META 2025 (R$) | N18: =IFERROR(SUM(B18:M18),"-") -> 0
A19: Receita REAL 2025 (R$) | N19: =IFERROR(SUM(B19:M19),"-") -> 0
A20: Receita META 2026 (R$) | N20: =IFERROR(SUM(B20:M20),"-") -> 0
A21: Receita REAL 2026 (R$) | N21: =IFERROR(SUM(B21:M21),"-") -> 0
A22: ATG% Real vs Meta | B22: =IFERROR(B19/B18,"-") -> - | C22: =IFERROR(C19/C18,"-") -> - | D22: =IFERROR(D19/D18,"-") -> - | E22: =IFERROR(E19/E18,"-") -> - | F22: =IFERROR(F19/F18,"-") -> - | G22: =IFERROR(G19/G18,"-") -> - | H22: =IFERROR(H19/H18,"-") -> - | I22: =IFERROR(I19/I18,"-") -> - | ... N22: =IFERROR(N19/N18,"-") -> -
A23: Investimento ADS (R$) | N23: =IFERROR(SUM(B23:M23),"-") -> 0
A24: ACOS (%) | B24: =IFERROR(B23/B19,"-") -> - | C24: =IFERROR(C23/C19,"-") -> - | D24: =IFERROR(D23/D19,"-") -> - | E24: =IFERROR(E23/E19,"-") -> - | F24: =IFERROR(F23/F19,"-") -> - | G24: =IFERROR(G23/G19,"-") -> - | H24: =IFERROR(H23/H19,"-") -> - | I24: =IFERROR(I23/I19,"-") -> - | ... N24: =IFERROR(N23/N19,"-") -> -
A25: ROAS | B25: =IFERROR(B19/B23,"-") -> - | C25: =IFERROR(C19/C23,"-") -> - | D25: =IFERROR(D19/D23,"-") -> - | E25: =IFERROR(E19/E23,"-") -> - | F25: =IFERROR(F19/F23,"-") -> - | G25: =IFERROR(G19/G23,"-") -> - | H25: =IFERROR(H19/H23,"-") -> - | I25: =IFERROR(I19/I23,"-") -> - | ... N25: =IFERROR(N19/N23,"-") -> -
A26: # Pedidos | N26: =IFERROR(SUM(B26:M26),"-") -> 0
A27: Ticket Médio (R$) | B27: =IFERROR(B19/B26,"-") -> - | C27: =IFERROR(C19/C26,"-") -> - | D27: =IFERROR(D19/D26,"-") -> - | E27: =IFERROR(E19/E26,"-") -> - | F27: =IFERROR(F19/F26,"-") -> - | G27: =IFERROR(G19/G26,"-") -> - | H27: =IFERROR(H19/H26,"-") -> - | I27: =IFERROR(I19/I26,"-") -> - | ... N27: =IFERROR(N19/N26,"-") -> -
A29: AMAZON
A30: MÉTRICA | B30: JAN | C30: FEV | D30: MAR | E30: ABR | F30: MAI | G30: JUN | H30: JUL | I30: AGO | J30: SET | K30: OUT | L30: NOV | M30: DEZ | N30: TOTAL
A31: Receita META 2025 (R$) | N31: =IFERROR(SUM(B31:M31),"-") -> 0
A32: Receita REAL 2025 (R$) | N32: =IFERROR(SUM(B32:M32),"-") -> 0
A33: Receita META 2026 (R$) | N33: =IFERROR(SUM(B33:M33),"-") -> 0
A34: Receita REAL 2026 (R$) | N34: =IFERROR(SUM(B34:M34),"-") -> 0
A35: ATG% Real vs Meta | B35: =IFERROR(B32/B31,"-") -> - | C35: =IFERROR(C32/C31,"-") -> - | D35: =IFERROR(D32/D31,"-") -> - | E35: =IFERROR(E32/E31,"-") -> - | F35: =IFERROR(F32/F31,"-") -> - | G35: =IFERROR(G32/G31,"-") -> - | H35: =IFERROR(H32/H31,"-") -> - | I35: =IFERROR(I32/I31,"-") -> - | ... N35: =IFERROR(N32/N31,"-") -> -
A36: Investimento ADS (R$) | N36: =IFERROR(SUM(B36:M36),"-") -> 0
A37: ACOS (%) | B37: =IFERROR(B36/B32,"-") -> - | C37: =IFERROR(C36/C32,"-") -> - | D37: =IFERROR(D36/D32,"-") -> - | E37: =IFERROR(E36/E32,"-") -> - | F37: =IFERROR(F36/F32,"-") -> - | G37: =IFERROR(G36/G32,"-") -> - | H37: =IFERROR(H36/H32,"-") -> - | I37: =IFERROR(I36/I32,"-") -> - | ... N37: =IFERROR(N36/N32,"-") -> -
A38: ROAS | B38: =IFERROR(B32/B36,"-") -> - | C38: =IFERROR(C32/C36,"-") -> - | D38: =IFERROR(D32/D36,"-") -> - | E38: =IFERROR(E32/E36,"-") -> - | F38: =IFERROR(F32/F36,"-") -> - | G38: =IFERROR(G32/G36,"-") -> - | H38: =IFERROR(H32/H36,"-") -> - | I38: =IFERROR(I32/I36,"-") -> - | ... N38: =IFERROR(N32/N36,"-") -> -
A39: # Pedidos | N39: =IFERROR(SUM(B39:M39),"-") -> 0
A40: Ticket Médio (R$) | B40: =IFERROR(B32/B39,"-") -> - | C40: =IFERROR(C32/C39,"-") -> - | D40: =IFERROR(D32/D39,"-") -> - | E40: =IFERROR(E32/E39,"-") -> - | F40: =IFERROR(F32/F39,"-") -> - | G40: =IFERROR(G32/G39,"-") -> - | H40: =IFERROR(H32/H39,"-") -> - | I40: =IFERROR(I32/I39,"-") -> - | ... N40: =IFERROR(N32/N39,"-") -> -
A42: MAGALU
A43: MÉTRICA | B43: JAN | C43: FEV | D43: MAR | E43: ABR | F43: MAI | G43: JUN | H43: JUL | I43: AGO | J43: SET | K43: OUT | L43: NOV | M43: DEZ | N43: TOTAL
A44: Receita META 2025 (R$) | N44: =IFERROR(SUM(B44:M44),"-") -> 0
...

Sheet 📆 Q2 DIÁRIO
A1: 📆 REPORT DIÁRIO Q2 2026 — MARKETPLACE | ABR · MAI · JUN
A2: 📘 Preencha as colunas azuis diariamente · ACOS · ROAS · Conv% · Acumulado calculados automaticamente
A3: ABRIL 2026 — META MENSAL (R$): | N3: =IFERROR('📊 ANUAL MKTPLACES'!E9,0) -> 0
A4: Data | B4: Dia | C4: Rec. Paga (R$) | D4: Rec. BI (R$) | E4: Pedidos | F4: Ticket Médio | G4: Visitas | H4: Conv% | I4: Inv. ADS (R$) | J4: ACOS | K4: ROAS | L4: ML Health | M4: Notas | N4: Acum. Rec.
A5: 46113 | B5: Qua | F5: =IFERROR(C5/E5,"-") -> - | H5: =IFERROR(E5/G5,"-") -> - | I5: 108 | J5: =IFERROR(I5/C5,"-") -> - | K5: =IFERROR(C5/I5,"-") -> 0 | N5: =SUM($C$5:C5) -> 0
A6: 46114 | B6: Qui | F6: =IFERROR(C6/E6,"-") -> - | H6: =IFERROR(E6/G6,"-") -> - | J6: =IFERROR(I6/C6,"-") -> - | K6: =IFERROR(C6/I6,"-") -> - | N6: =SUM($C$5:C6) -> 0
A7: 46115 | B7: Sex | F7: =IFERROR(C7/E7,"-") -> - | H7: =IFERROR(E7/G7,"-") -> - | J7: =IFERROR(I7/C7,"-") -> - | K7: =IFERROR(C7/I7,"-") -> - | N7: =SUM($C$5:C7) -> 0
A8: 46116 | B8: Sáb | F8: =IFERROR(C8/E8,"-") -> - | H8: =IFERROR(E8/G8,"-") -> - | J8: =IFERROR(I8/C8,"-") -> - | K8: =IFERROR(C8/I8,"-") -> - | N8: =SUM($C$5:C8) -> 0
A9: 46117 | B9: Dom | F9: =IFERROR(C9/E9,"-") -> - | H9: =IFERROR(E9/G9,"-") -> - | J9: =IFERROR(I9/C9,"-") -> - | K9: =IFERROR(C9/I9,"-") -> - | N9: =SUM($C$5:C9) -> 0
A10: 46118 | B10: Seg | F10: =IFERROR(C10/E10,"-") -> - | H10: =IFERROR(E10/G10,"-") -> - | J10: =IFERROR(I10/C10,"-") -> - | K10: =IFERROR(C10/I10,"-") -> - | N10: =SUM($C$5:C10) -> 0
A11: 46119 | B11: Ter | F11: =IFERROR(C11/E11,"-") -> - | H11: =IFERROR(E11/G11,"-") -> - | J11: =IFERROR(I11/C11,"-") -> - | K11: =IFERROR(C11/I11,"-") -> - | N11: =SUM($C$5:C11) -> 0
A12: 46120 | B12: Qua | F12: =IFERROR(C12/E12,"-") -> - | H12: =IFERROR(E12/G12,"-") -> - | J12: =IFERROR(I12/C12,"-") -> - | K12: =IFERROR(C12/I12,"-") -> - | N12: =SUM($C$5:C12) -> 0
A13: 46121 | B13: Qui | F13: =IFERROR(C13/E13,"-") -> - | H13: =IFERROR(E13/G13,"-") -> - | J13: =IFERROR(I13/C13,"-") -> - | K13: =IFERROR(C13/I13,"-") -> - | N13: =SUM($C$5:C13) -> 0
A14: 46122 | B14: Sex | F14: =IFERROR(C14/E14,"-") -> - | H14: =IFERROR(E14/G14,"-") -> - | J14: =IFERROR(I14/C14,"-") -> - | K14: =IFERROR(C14/I14,"-") -> - | N14: =SUM($C$5:C14) -> 0
A15: 46123 | B15: Sáb | F15: =IFERROR(C15/E15,"-") -> - | H15: =IFERROR(E15/G15,"-") -> - | J15: =IFERROR(I15/C15,"-") -> - | K15: =IFERROR(C15/I15,"-") -> - | N15: =SUM($C$5:C15) -> 0
A16: 46124 | B16: Dom | F16: =IFERROR(C16/E16,"-") -> - | H16: =IFERROR(E16/G16,"-") -> - | J16: =IFERROR(I16/C16,"-") -> - | K16: =IFERROR(C16/I16,"-") -> - | N16: =SUM($C$5:C16) -> 0
A17: 46125 | B17: Seg | F17: =IFERROR(C17/E17,"-") -> - | H17: =IFERROR(E17/G17,"-") -> - | J17: =IFERROR(I17/C17,"-") -> - | K17: =IFERROR(C17/I17,"-") -> - | N17: =SUM($C$5:C17) -> 0
... A34: 46142 | B34: Qui | F34: =IFERROR(C34/E34,"-") -> - | H34: =IFERROR(E34/G34,"-") -> - | J34: =IFERROR(I34/C34,"-") -> - | K34: =IFERROR(C34/I34,"-") -> - | N34: =SUM($C$5:C34) -> 0
A35: TOTAL ABRIL 2026 | C35: =SUM(C5:C34) -> 0 | D35: =SUM(D5:D34) -> 0 | E35: =SUM(E5:E34) -> 0 | F35: =IFERROR(C35/E35,"-") -> - | G35: =SUM(G5:G34) -> 0 | H35: =IFERROR(E35/G35,"-") -> - | I35: =SUM(I5:I34) -> 108 | J35: =IFERROR(I35/C35,"-") -> - | K35: =IFERROR(C35/I35,"-") -> 0 | L35: ATG% vs Meta: | N35: =IFERROR(C35/'📊 ANUAL MKTPLACES'!E9,"-") -> -
A37: MAIO 2026 — META MENSAL (R$): | N37: =IFERROR('📊 ANUAL MKTPLACES'!F9,0) -> 0
A38: Data | B38: Dia | C38: Rec. Paga (R$) | D38: Rec. BI (R$) | E38: Pedidos | F38: Ticket Médio | G38: Visitas | H38: Conv% | I38: Inv. ADS (R$) | J38: ACOS | K38: ROAS | L38: ML Health | M38: Notas | N38: Acum. Rec.
A39: 46143 | B39: Sex | F39: =IFERROR(C39/E39,"-") -> - | H39: =IFERROR(E39/G39,"-") -> - | J39: =IFERROR(I39/C39,"-") -> - | K39: =IFERROR(C39/I39,"-") -> - | N39: =SUM($C$39:C39) -> 0
A40: 46144 | B40: Sáb | F40: =IFERROR(C40/E40,"-") -> - | H40: =IFERROR(E40/G40,"-") -> - | J40: =IFERROR(I40/C40,"-") -> - | K40: =IFERROR(C40/I40,"-") -> - | N40: =SUM($C$39:C40) -> 0
A41: 46145 | B41: Dom | F41: =IFERROR(C41/E41,"-") -> - | H41: =IFERROR(E41/G41,"-") -> - | J41: =IFERROR(I41/C41,"-") -> - | K41: =IFERROR(C41/I41,"-") -> - | N41: =SUM($C$39:C41) -> 0
A42: 46146 | B42: Seg | F42: =IFERROR(C42/E42,"-") -> - | H42: =IFERROR(E42/G42,"-") -> - | J42: =IFERROR(I42/C42,"-") -> - | K42: =IFERROR(C42/I42,"-") -> - | N42: =SUM($C$39:C42) -> 0
A43: 46147 | B43: Ter | F43: =IFERROR(C43/E43,"-") -> - | H43: =IFERROR(E43/G43,"-") -> - | J43: =IFERROR(I43/C43,"-") -> - | K43: =IFERROR(C43/I43,"-") -> - | N43: =SUM($C$39:C43) -> 0
A44: 46148 | B44: Qua | F44: =IFERROR(C44/E44,"-") -> - | H44: =IFERROR(E44/G44,"-") -> - | J44: =IFERROR(I44/C44,"-") -> - | K44: =IFERROR(C44/I44,"-") -> - | N44: =SUM($C$39:C44) -> 0
A45: 46149 | B45: Qui | F45: =IFERROR(C45/E45,"-") -> - | H45: =IFERROR(E45/G45,"-") -> - | J45: =IFERROR(I45/C45,"-") -> - | K45: =IFERROR(C45/I45,"-") -> - | N45: =SUM($C$39:C45) -> 0
A46: 46150 | B46: Sex | F46: =IFERROR(C46/E46,"-") -> - | H46: =IFERROR(E46/G46,"-") -> - | J46: =IFERROR(I46/C46,"-") -> - | K46: =IFERROR(C46/I46,"-") -> - | N46: =SUM($C$39:C46) -> 0
A47: 46151 | B47: Sáb | F47: =IFERROR(C47/E47,"-") -> - | H47: =IFERROR(E47/G47,"-") -> - | J47: =IFERROR(I47/C47,"-") -> - | K47: =IFERROR(C47/I47,"-") -> - | N47: =SUM($C$39:C47) -> 0
A48: 46152 | B48: Dom | F48: =IFERROR(C48/E48,"-") -> - | H48: =IFERROR(E48/G48,"-") -> - | J48: =IFERROR(I48/C48,"-") -> - | K48: =IFERROR(C48/I48,"-") -> - | N48: =SUM($C$39:C48) -> 0
A49: 46153 | B49: Seg | F49: =IFERROR(C49/E49,"-") -> - | H49: =IFERROR(E49/G49,"-") -> - | J49: =IFERROR(I49/C49,"-") -> - | K49: =IFERROR(C49/I49,"-") -> - | N49: =SUM($C$39:C49) -> 0
A50: 46154 | B50: Ter | F50: =IFERROR(C50/E50,"-") -> - | H50: =IFERROR(E50/G50,"-") -> - | J50: =IFERROR(I50/C50,"-") -> - | K50: =IFERROR(C50/I50,"-") -> - | N50: =SUM($C$39:C50) -> 0
... A69: 46173 | B69: Dom | F69: =IFERROR(C69/E69,"-") -> - | H69: =IFERROR(E69/G69,"-") -> - | J69: =IFERROR(I69/C69,"-") -> - | K69: =IFERROR(C69/I69,"-") -> - | N69: =SUM($C$39:C69) -> 0
A70: TOTAL MAIO 2026 | C70: =SUM(C39:C69) -> 0 | D70: =SUM(D39:D69) -> 0 | E70: =SUM(E39:E69) -> 0 | F70: =IFERROR(C70/E70,"-") -> - | G70: =SUM(G39:G69) -> 0 | H70: =IFERROR(E70/G70,"-") -> - | I70: =SUM(I39:I69) -> 0 | J70: =IFERROR(I70/C70,"-") -> - | K70: =IFERROR(C70/I70,"-") -> - | L70: ATG% vs Meta: | N70: =IFERROR(C70/'📊 ANUAL MKTPLACES'!F9,"-") -> -
A72: JUNHO 2026 — META MENSAL (R$): | N72: =IFERROR('📊 ANUAL MKTPLACES'!G9,0) -> 0
A73: Data | B73: Dia | C73: Rec. Paga (R$) | D73: Rec. BI (R$) | E73: Pedidos | F73: Ticket Médio | G73: Visitas | H73: Conv% | I73: Inv. ADS (R$) | J73: ACOS | K73: ROAS | L73: ML Health | M73: Notas | N73: Acum. Rec.
A74: 46174 | B74: Seg | F74: =IFERROR(C74/E74,"-") -> - | H74: =IFERROR(E74/G74,"-") -> - | J74: =IFERROR(I74/C74,"-") -> - | K74: =IFERROR(C74/I74,"-") -> - | N74: =SUM($C$74:C74) -> 0
A75: 46175 | B75: Ter | F75: =IFERROR(C75/E75,"-") -> - | H75: =IFERROR(E75/G75,"-") -> - | J75: =IFERROR(I75/C75,"-") -> - | K75: =IFERROR(C75/I75,"-") -> - | N75: =SUM($C$74:C75) -> 0
A76: 46176 | B76: Qua | F76: =IFERROR(C76/E76,"-") -> - | H76: =IFERROR(E76/G76,"-") -> - | J76: =IFERROR(I76/C76,"-") -> - | K76: =IFERROR(C76/I76,"-") -> - | N76: =SUM($C$74:C76) -> 0
...

Sheet 📈 SEMANAL
A1: 📈 ACOMPANHAMENTO SEMANAL — MARKETPLACE 2025 & 2026
A2: 📘 Preencha as colunas azuis. Meta semanal puxada do Anual (÷ 4,3 semanas) · ACOS, ROAS e Conv% automáticos.
A3: ▶ ANO 2025 — preencha conforme dados chegam
A4: Q1 2025 — JAN | FEV | MAR
A5: Semana | B5: Período | C5: Canal Principal | D5: Meta Sem. (R$) | E5: Real (R$) | F5: ATG% | G5: Inv. ADS (R$) | H5: ACOS | I5: ROAS | J5: Pedidos | K5: Ticket Médio | L5: Visitas | M5: Conv%
A6: S01 | B6: 06/01 – 12/01/25 | D6: =IFERROR('📊 ANUAL MKTPLACES'!B5/4.33,0) -> 0 | F6: =IFERROR(E6/D6,"-") -> - | H6: =IFERROR(G6/E6,"-") -> - | I6: =IFERROR(E6/G6,"-") -> - | M6: =IFERROR(J6/L6,"-") -> -
A7: S02 | B7: 13/01 – 19/01/25 | D7: =IFERROR('📊 ANUAL MKTPLACES'!B5/4.33,0) -> 0 | F7: =IFERROR(E7/D7,"-") -> - | H7: =IFERROR(G7/E7,"-") -> - | I7: =IFERROR(E7/G7,"-") -> - | M7: =IFERROR(J7/L7,"-") -> -
A8: S03 | B8: 20/01 – 26/01/25 | D8: =IFERROR('📊 ANUAL MKTPLACES'!B5/4.33,0) -> 0 | F8: =IFERROR(E8/D8,"-") -> - | H8: =IFERROR(G8/E8,"-") -> - | I8: =IFERROR(E8/G8,"-") -> - | M8: =IFERROR(J8/L8,"-") -> -
A9: S04 | B9: 27/01 – 02/02/25 | D9: =IFERROR('📊 ANUAL MKTPLACES'!B5/4.33,0) -> 0 | F9: =IFERROR(E9/D9,"-") -> - | H9: =IFERROR(G9/E9,"-") -> - | I9: =IFERROR(E9/G9,"-") -> - | M9: =IFERROR(J9/L9,"-") -> -
A10: S05 | B10: 03/02 – 09/02/25 | D10: =IFERROR('📊 ANUAL MKTPLACES'!C5/4.33,0) -> 0 | F10: =IFERROR(E10/D10,"-") -> - | H10: =IFERROR(G10/E10,"-") -> - | I10: =IFERROR(E10/G10,"-") -> - | M10: =IFERROR(J10/L10,"-") -> -
A11: S06 | B11: 10/02 – 16/02/25 | D11: =IFERROR('📊 ANUAL MKTPLACES'!C5/4.33,0) -> 0 | F11: =IFERROR(E11/D11,"-") -> - | H11: =IFERROR(G11/E11,"-") -> - | I11: =IFERROR(E11/G11,"-") -> - | M11: =IFERROR(J11/L11,"-") -> -
A12: S07 | B12: 17/02 – 23/02/25 | D12: =IFERROR('📊 ANUAL MKTPLACES'!C5/4.33,0) -> 0 | F12: =IFERROR(E12/D12,"-") -> - | H12: =IFERROR(G12/E12,"-") -> - | I12: =IFERROR(E12/G12,"-") -> - | M12: =IFERROR(J12/L12,"-") -> -
A13: S08 | B13: 24/02 – 02/03/25 | D13: =IFERROR('📊 ANUAL MKTPLACES'!C5/4.33,0) -> 0 | F13: =IFERROR(E13/D13,"-") -> - | H13: =IFERROR(G13/E13,"-") -> - | I13: =IFERROR(E13/G13,"-") -> - | M13: =IFERROR(J13/L13,"-") -> -
A14: S09 | B14: 03/03 – 09/03/25 | D14: =IFERROR('📊 ANUAL MKTPLACES'!D5/4.33,0) -> 0 | F14: =IFERROR(E14/D14,"-") -> - | H14: =IFERROR(G14/E14,"-") -> - | I14: =IFERROR(E14/G14,"-") -> - | M14: =IFERROR(J14/L14,"-") -> -
A15: S10 | B15: 10/03 – 16/03/25 | D15: =IFERROR('📊 ANUAL MKTPLACES'!D5/4.33,0) -> 0 | F15: =IFERROR(E15/D15,"-") -> - | H15: =IFERROR(G15/E15,"-") -> - | I15: =IFERROR(E15/G15,"-") -> - | M15: =IFERROR(J15/L15,"-") -> -
A16: S11 | B16: 17/03 – 23/03/25 | D16: =IFERROR('📊 ANUAL MKTPLACES'!D5/4.33,0) -> 0 | F16: =IFERROR(E16/D16,"-") -> - | H16: =IFERROR(G16/E16,"-") -> - | I16: =IFERROR(E16/G16,"-") -> - | M16: =IFERROR(J16/L16,"-") -> -
A17: S12 | B17: 24/03 – 30/03/25 | D17: =IFERROR('📊 ANUAL MKTPLACES'!D5/4.33,0) -> 0 | F17: =IFERROR(E17/D17,"-") -> - | H17: =IFERROR(G17/E17,"-") -> - | I17: =IFERROR(E17/G17,"-") -> - | M17: =IFERROR(J17/L17,"-") -> -
A18: TOTAL Q1 | D18: =IFERROR(SUM(D6:D17),"-") -> 0 | E18: =IFERROR(SUM(E6:E17),"-") -> 0 | F18: =IFERROR(E18/D18,"-") -> - | G18: =IFERROR(SUM(G6:G17),"-") -> 0 | H18: =IFERROR(G18/E18,"-") -> - | I18: =IFERROR(E18/G18,"-") -> - | J18: =IFERROR(SUM(J6:J17),"-") -> 0 | K18: =IFERROR(E18/J18,"-") -> - | L18: =IFERROR(SUM(L6:L17),"-") -> 0 | M18: =IFERROR(J18/L18,"-") -> -
A20: Q2 2025 — ABR | MAI | JUN
A21: Semana | B21: Período | C21: Canal Principal | D21: Meta Sem. (R$) | E21: Real (R$) | F21: ATG% | G21: Inv. ADS (R$) | H21: ACOS | I21: ROAS | J21: Pedidos | K21: Ticket Médio | L21: Visitas | M21: Conv%
A22: S14 | B22: 07/04 – 13/04/25 | D22: =IFERROR('📊 ANUAL MKTPLACES'!E5/4.33,0) -> 0 | F22: =IFERROR(E22/D22,"-") -> - | H22: =IFERROR(G22/E22,"-") -> - | I22: =IFERROR(E22/G22,"-") -> - | M22: =IFERROR(J22/L22,"-") -> -
A23: S15 | B23: 14/04 – 20/04/25 | D23: =IFERROR('📊 ANUAL MKTPLACES'!E5/4.33,0) -> 0 | F23: =IFERROR(E23/D23,"-") -> - | H23: =IFERROR(G23/E23,"-") -> - | I23: =IFERROR(E23/G23,"-") -> - | M23: =IFERROR(J23/L23,"-") -> -
A24: S16 | B24: 21/04 – 27/04/25 | D24: =IFERROR('📊 ANUAL MKTPLACES'!E5/4.33,0) -> 0 | F24: =IFERROR(E24/D24,"-") -> - | H24: =IFERROR(G24/E24,"-") -> - | I24: =IFERROR(E24/G24,"-") -> - | M24: =IFERROR(J24/L24,"-") -> -
A25: S17 | B25: 28/04 – 04/05/25 | D25: =IFERROR('📊 ANUAL MKTPLACES'!F5/4.33,0) -> 0 | F25: =IFERROR(E25/D25,"-") -> - | H25: =IFERROR(G25/E25,"-") -> - | I25: =IFERROR(E25/G25,"-") -> - | M25: =IFERROR(J25/L25,"-") -> -
A26: S18 | B26: 05/05 – 11/05/25 | D26: =IFERROR('📊 ANUAL MKTPLACES'!F5/4.33,0) -> 0 | F26: =IFERROR(E26/D26,"-") -> - | H26: =IFERROR(G26/E26,"-") -> - | I26: =IFERROR(E26/G26,"-") -> - | M26: =IFERROR(J26/L26,"-") -> -
A27: S19 | B27: 12/05 – 18/05/25 | D27: =IFERROR('📊 ANUAL MKTPLACES'!F5/4.33,0) -> 0 | F27: =IFERROR(E27/D27,"-") -> - | H27: =IFERROR(G27/E27,"-") -> - | I27: =IFERROR(E27/G27,"-") -> - | M27: =IFERROR(J27/L27,"-") -> -
A28: S20 | B28: 19/05 – 25/05/25 | D28: =IFERROR('📊 ANUAL MKTPLACES'!F5/4.33,0) -> 0 | F28: =IFERROR(E28/D28,"-") -> - | H28: =IFERROR(G28/E28,"-") -> - | I28: =IFERROR(E28/G28,"-") -> - | M28: =IFERROR(J28/L28,"-") -> -
A29: S21 | B29: 26/05 – 01/06/25 | D29: =IFERROR('📊 ANUAL MKTPLACES'!F5/4.33,0) -> 0 | F29: =IFERROR(E29/D29,"-") -> - | H29: =IFERROR(G29/E29,"-") -> - | I29: =IFERROR(E29/G29,"-") -> - | M29: =IFERROR(J29/L29,"-") -> -
A30: S22 | B30: 02/06 – 08/06/25 | D30: =IFERROR('📊 ANUAL MKTPLACES'!G5/4.33,0) -> 0 | F30: =IFERROR(E30/D30,"-") -> - | H30: =IFERROR(G30/E30,"-") -> - | I30: =IFERROR(E30/G30,"-") -> - | M30: =IFERROR(J30/L30,"-") -> -
A31: S23 | B31: 09/06 – 15/06/25 | D31: =IFERROR('📊 ANUAL MKTPLACES'!G5/4.33,0) -> 0 | F31: =IFERROR(E31/D31,"-") -> - | H31: =IFERROR(G31/E31,"-") -> - | I31: =IFERROR(E31/G31,"-") -> - | M31: =IFERROR(J31/L31,"-") -> -
A32: S24 | B32: 16/06 – 22/06/25 | D32: =IFERROR('📊 ANUAL MKTPLACES'!G5/4.33,0) -> 0 | F32: =IFERROR(E32/D32,"-") -> - | H32: =IFERROR(G32/E32,"-") -> - | I32: =IFERROR(E32/G32,"-") -> - | M32: =IFERROR(J32/L32,"-") -> -
A33: S25 | B33: 23/06 – 29/06/25 | D33: =IFERROR('📊 ANUAL MKTPLACES'!G5/4.33,0) -> 0 | F33: =IFERROR(E33/D33,"-") -> - | H33: =IFERROR(G33/E33,"-") -> - | I33: =IFERROR(E33/G33,"-") -> - | M33: =IFERROR(J33/L33,"-") -> -
A34: TOTAL Q2 | D34: =IFERROR(SUM(D22:D33),"-") -> 0 | E34: =IFERROR(SUM(E22:E33),"-") -> 0 | F34: =IFERROR(E34/D34,"-") -> - | G34: =IFERROR(SUM(G22:G33),"-") -> 0 | H34: =IFERROR(G34/E34,"-") -> - | I34: =IFERROR(E34/G34,"-") -> - | J34: =IFERROR(SUM(J22:J33),"-") -> 0 | K34: =IFERROR(E34/J34,"-") -> - | L34: =IFERROR(SUM(L22:L33),"-") -> 0 | M34: =IFERROR(J34/L34,"-") -> -
A36: Q3 2025 — JUL | AGO | SET
A37: Semana | B37: Período | C37: Canal Principal | D37: Meta Sem. (R$) | E37: Real (R$) | F37: ATG% | G37: Inv. ADS (R$) | H37: ACOS | I37: ROAS | J37: Pedidos | K37: Ticket Médio | L37: Visitas | M37: Conv%
A38: S27 | B38: 07/07 – 13/07/25 | D38: =IFERROR('📊 ANUAL MKTPLACES'!H5/4.33,0) -> 0 | F38: =IFERROR(E38/D38,"-") -> - | H38: =IFERROR(G38/E38,"-") -> - | I38: =IFERROR(E38/G38,"-") -> - | M38: =IFERROR(J38/L38,"-") -> -
A39: S28 | B39: 14/07 – 20/07/25 | D39: =IFERROR('📊 ANUAL MKTPLACES'!H5/4.33,0) -> 0 | F39: =IFERROR(E39/D39,"-") -> - | H39: =IFERROR(G39/E39,"-") -> - | I39: =IFERROR(E39/G39,"-") -> - | M39: =IFERROR(J39/L39,"-") -> -
A40: S29 | B40: 21/07 – 27/07/25 | D40: =IFERROR('📊 ANUAL MKTPLACES'!H5/4.33,0) -> 0 | F40: =IFERROR(E40/D40,"-") -> - | H40: =IFERROR(G40/E40,"-") -> - | I40: =IFERROR(E40/G40,"-") -> - | M40: =IFERROR(J40/L40,"-") -> -
A41: S30 | B41: 28/07 – 03/08/25 | D41: =IFERROR('📊 ANUAL MKTPLACES'!H5/4.33,0) -> 0 | F41: =IFERROR(E41/D41,"-") -> - | H41: =IFERROR(G41/E41,"-") -> - | I41: =IFERROR(E41/G41,"-") -> - | M41: =IFERROR(J41/L41,"-") -> -
A42: S31 | B42: 04/08 – 10/08/25 | D42: =IFERROR('📊 ANUAL MKTPLACES'!I5/4.33,0) -> 0 | F42: =IFERROR(E42/D42,"-") -> - | H42: =IFERROR(G42/E42,"-") -> - | I42: =IFERROR(E42/G42,"-") -> - | M42: =IFERROR(J42/L42,"-") -> -
...
